#include <iostream>
namespace exception_in_desctructor
{
    using namespace std;

    struct E {
        const char* message;
        E(const char* arg) : message(arg) { }
    };

    void my_terminate() {
        cout << "Call to my_terminate" << endl;
        exit(0);
    };

    struct A {
        A() { cout << "In constructor of A" << endl; }
        ~A() {
            cout << "In destructor of A" << endl;
            throw E("Exception thrown in ~A()");
        }
    };

    struct B {
        B() { cout << "In constructor of B" << endl; }
        ~B() { cout << "In destructor of B" << endl; }
    };

    void  test() {
        set_terminate(my_terminate);
        try {
            cout << "In try block" << endl;
            A a;
            B b;
            throw("Exception thrown in try block of main()");
        }
        catch (const char* e) {
            cout << "Exception: " << e << endl;
        }
        catch (...) {
            cout << "Some exception caught in main()" << endl;
        }

        cout << "Resume execution of main()" << endl;
    }
}